<!DOCTYPE html><html lang="zh-CN"><head><title>Promise</title><meta http-equiv="content-type" content="text/html; charset=utf-8"><meta name="viewport" content="width=device-width, initial-scale=0.5"><link rel="stylesheet" href="/css/highlight/xcode.min.css"><link rel="icon" href="https://unpkg.com/gitimages/favicon.ico"><link rel="stylesheet" href="/css/post.css"><meta name="generator" content="Hexo 6.0.0"></head><body><div class="inner"><h1>Promise</h1><div class="time">First published 2023-04-11</div><div class="updatedTime">Modified 2023-04-11</div><h2 id="Resolving-Promise-解决承诺"><a href="#Resolving-Promise-解决承诺" class="headerlink" title="Resolving Promise 解决承诺"></a>Resolving Promise 解决承诺</h2><p>fetch返回一个Pormise对象，该对象完成时将一个Response对象传递给我们使用.then注册的回调函数，Response对象具有.text(),.json()和其他方法，用于以各种形式请求HTTP响应的正文。然而，响应主体可能尚未到达，因此这些方法只能先返回一个Promise对象。</p>
<pre><code class="js">// URL-fetch的示例代码
// 两个回调函数
function c1(response) &#123;
  let p4 = response.json();
  return p4;
&#125;
function c2(profile) &#123;
  displayUserProfile(profile);
&#125;
// Promise链
let p1 = fetch(&quot;/api/user/profile&quot;); // task 1, Promise 1
let p2 = p1.then(c1); // task 2, Promise 2
let p3 = p2.then(c2); // task 3, Promise 3
</code></pre>
<p>当我们将回调c传递给then方法时，then会返回一个Promise p，并安排在以后某个时间异步调用c，回调c执行一些计算并返回一个值v。当回调返回时，p用值v来解析（resolved）。当一个Promise被用一个本身不是Promise的值来解析时，它会立即用该值来实现。所以，如果c返回一个非Promise值，那么返回值就变成了p的值，p就实现了，我们就完成了。但如果返回值v本身就是一个Promise，那么p是resolved解决了，但还没有fulfilled实现。在这个阶段，Promise v结算settled之前，p不能结算。如果v被实现，那么p也被实现为相同的值，v被拒绝rejected，p也会以同样的原因被拒绝。这就是Promise的已解决resolved的含义：该Promise已经与另一个Promise相关联或者“锁定”了。我们不知道p将被实现或者被拒绝，但我们的回调c不对此进行任何控制。Promise p是resolved已解决的意思就相当于是，Promise p的命运现在完全取决于Promise v将会发生什么。</p>
<p>回到这个例子中，当c1返回p4时，p2被p4解决。但解决了p2并不等于完成了任务2，要完成必须要结算（拒绝或者实现），因此任务3还没有开始。当HTTP响应的整个正文可用时，.json()方法可以解析它并使用解析后的值来实现p4时，当实现p4时，p2也将以p4的值自动实现，具有相同的解析后的json值。此时，解析后的json对象被传递到c2中，任务3才会开始。</p>
<h2 id="More-on-Promise-and-errors-处理Promise中的错误"><a href="#More-on-Promise-and-errors-处理Promise中的错误" class="headerlink" title="More on Promise and errors 处理Promise中的错误"></a>More on Promise and errors 处理Promise中的错误</h2><p>可以将第二个回调函数传递到then方法中，如果Promise被拒绝，则会调用第二个回调函数。当发生这种情况时，第二个回调函数的参数是一个值，通常是一个错误对象，表示拒绝的原因。但将两个回调函数传递给then是不常见的，并非通常做法。与Promise相关的错误通常通过向Promise链添加一个catch方法调用来处理。在开始讨论catch方法之前，需要强调的是，在进行异步编程时，仔细的错误处理非常重要，对于同步代码来说，如果省略了错误处理代码，您至少能得到一个异常和堆栈跟踪，你可以利用他们来找出哪里出了问题。对于异步代码，未处理的异常通常不会被报告，并且错误可以静默发生，这让调试它们变得更加难过。好消息是，catch方法使Promise的错误处理变得很容易。</p>
<p>Promise的catch方法只是then的一种简写方式，第一个参数为null，第二个参数为错误处理回调函数，以下两行代码是等价的：</p>
<pre><code class="js">p.then(null, c);
p.catch(c)
</code></pre>
<p>最好使用catch，名称与try&#x2F;catch异常处理语句的catch子句匹配，但同步异常处理不适用于异步代码。Promise的catch方法是一种适用于异步代码错误处理的替代方法。当同步代码中出现错误时，我们可以说异常“冒泡出现在调用栈中”，直到找到catch块，对于异步的Promise链，类似的比喻是异常“沿着链向下渗透”，直到找到catch函数调用。</p>
<p>在ES2018中，Promise还定义了一个finally方法，其用途类似于try&#x2F;catch&#x2F;finally的finally子句，如果在Promise链中添加了一个finally调用，那么当该Promise结算settled时，将调用您传递给finally的回调函数。无论Promise是实现或者拒绝，都会调用finally的回调，但不会向它传递任何参数，因此你也无法知道它是实现还是拒绝。但，如果这两种情况都需要运行某种清理代码（例如关闭打开的文件或网络连接等等操作），则finally回调是实现这一目的的理想方法。与then和catch一样，finally返回一个新的Promise对象。finally回调的返回值通常被忽略，并且finally返回的Promise通常与finally回调返回的Promise以相同的值解析或拒绝。</p>
<p>我们在前面的URL-fetch的示例代码中没执行任何错误处理，现在我们用一个更实际的代码来纠正这一点：</p>
<pre><code class="js">
</code></pre>
<p class="backHome"><span></span><a href="/">Back</a><span>↶</span></p></div><script src="/js/highlight.min.js"></script><script src="/js/jquery.min.js"></script><script src="/js/main.js"></script></body></html>